Workbook

Sheet Cover
B2: VAT Expense Checklist
B4: Dubai / UAE - Federal Tax Authority (FTA) Compliance
B6: Company Name:
B7: TRN Number:
B8: Tax Period:
B9: Prepared By:
B10: Date Prepared:
B11: Reviewed By:
B13: How to Use This Checklist
B14: 1. Go through each expense category in the 'Recoverable', 'Blocked', and 'Mixed-Use' sheets.
B15: 2. Tick the checkbox column for each expense you have incurred during the tax period.
B16: 3. Enter the amount (AED) and VAT amount (AED) in the respective columns.
... B28: - Expenses related to exempt supplies are NOT recoverable

Sheet Recoverable
B2: RECOVERABLE EXPENSES
B3: Input VAT can be claimed (5% recovery rate)
B4: Check | C4: Expense Item | D4: Details / Examples | E4: Amount (AED) | F4: VAT (AED) | G4: Invoice Ref.
B5: OFFICE & ADMINISTRATIVE
B6: [ ] | C6: Commercial Office Rent | D6: VAT-registered landlord charging 5%
B7: [ ] | C7: Office Furniture | D7: Desks, chairs, cabinets, shelves, partitions
B8: [ ] | C8: Stationery & Supplies | D8: Paper, pens, folders, binders, notebooks, sticky notes
B9: [ ] | C9: Printers & Scanners | D9: Purchase or lease of office printing equipment
B10: [ ] | C10: Toner & Ink Cartridges | D10: Consumables for printers and copiers
B11: [ ] | C11: Cleaning Services | D11: Office cleaning and janitorial services
B12: [ ] | C12: Security Services | D12: Office building security guard services
B13: [ ] | C13: Office Maintenance & Repairs | D13: Minor repairs, painting, plumbing, electrical
B14: [ ] | C14: DEWA - Electricity | D14: Commercial electricity bills
B15: [ ] | C15: DEWA - Water | D15: Commercial water bills
B16: [ ] | C16: Empower / District Cooling | D16: Commercial cooling charges
B17: [ ] | C17: Internet (du / Etisalat) | D17: Business internet connection
... B21: [ ] | C21: PO Box Rental | D21: Annual PO Box rental from Emirates Post
B23: IT & SOFTWARE
B24: [ ] | C24: Computers & Laptops | D24: Purchase of desktops, laptops for staff
B25: [ ] | C25: Servers & Networking | D25: Switches, routers, cables, servers
B26: [ ] | C26: Business Software Licenses | D26: CRM, accounting, ERP software licenses
B27: [ ] | C27: Cloud Hosting | D27: AWS, Azure, Google Cloud services
B28: [ ] | C28: SaaS Subscriptions | D28: Microsoft 365, Google Workspace, Slack, Zoom
B29: [ ] | C29: Website Domain & Hosting | D29: Domain registration, SSL, web hosting
B30: [ ] | C30: Antivirus & Cybersecurity | D30: Security software and services
B31: [ ] | C31: IT Support & Maintenance | D31: External IT support contracts
B32: [ ] | C32: Data Storage & Backup | D32: Cloud backup and storage services
B34: PROFESSIONAL SERVICES
B35: [ ] | C35: External Audit Fees | D35: Annual statutory audit fees
B36: [ ] | C36: Accounting & Bookkeeping | D36: Outsourced accounting services
B37: [ ] | C37: Legal Consultation | D37: Legal retainer and advisory fees
B38: [ ] | C38: Tax & VAT Advisory | D38: Tax agent fees, VAT return filing services
B39: [ ] | C39: Management Consulting | D39: Strategy and operational consulting
B40: [ ] | C40: HR & Recruitment Agency | D40: Recruitment agency placement fees
B41: [ ] | C41: Employee Training | D41: Training courses and certifications
B42: [ ] | C42: Translation Services | D42: Legal and business translation
B43: [ ] | C43: Engineering / Architecture | D43: Consultancy for office fit-out or projects
B45: MARKETING & ADVERTISING
B46: [ ] | C46: Digital Advertising | D46: Google Ads, Facebook Ads, LinkedIn Ads
B47: [ ] | C47: Social Media Management | D47: Social media management tools and services
...

Sheet Blocked
B2: BLOCKED / NON-RECOVERABLE EXPENSES
B3: Input VAT CANNOT be claimed (treated as business cost)
B4: Check | C4: Expense Item | D4: Details / Examples | E4: Amount (AED) | F4: VAT (AED) | G4: Invoice Ref.
B5: ENTERTAINMENT
B6: [ ] | C6: Client Dinners & Lunches | D6: Social/entertainment meals with clients
B7: [ ] | C7: Client Hotel Stays | D7: Accommodation for client entertainment
B8: [ ] | C8: Event & Show Tickets | D8: Concerts, shows, sporting events for clients
B9: [ ] | C9: Leisure Trips & Excursions | D9: Trips provided for pleasure/entertainment
B10: [ ] | C10: Gifts & Giveaways | D10: Gifts to clients, suppliers, non-employees
B11: [ ] | C11: Free Samples | D11: Free product samples distributed
B12: [ ] | C12: Staff Holiday Parties | D12: Seasonal parties and celebrations
B13: [ ] | C13: Team Building (Social) | D13: Social team building events and retreats
B15: MOTOR VEHICLES (PERSONAL USE)
B16: [ ] | C16: Car Purchase (Personal Use) | D16: Vehicles available for personal use
B17: [ ] | C17: Car Lease (Personal Use) | D17: Lease/rental of vehicles for personal use
B18: [ ] | C18: Fuel (Personal Use) | D18: Petrol for personal vehicle use
B19: [ ] | C19: Insurance (Personal Vehicle) | D19: Insurance for personal-use vehicles
B21: PERSONAL & NON-BUSINESS
B22: [ ] | C22: Owner's Personal Expenses | D22: Personal costs charged to business
B23: [ ] | C23: Personal Phone Bills | D23: Non-business mobile/landline charges
B24: [ ] | C24: Personal Travel | D24: Non-business trips and holidays
B25: [ ] | C25: Personal Groceries | D25: Personal food and household items
B26: [ ] | C26: School Fees (Owner's Children) | D26: Education expenses for owners' families
B28: EXEMPT SUPPLY-RELATED
B29: [ ] | C29: Residential Property Rent | D29: Rent for residential property
B30: [ ] | C30: Bare Land Purchase | D30: Purchase of undeveloped land without buildings
B31: [ ] | C31: Local Passenger Transport | D31: Taxi, bus, metro for local transport
B32: [ ] | C32: Certain Financial Services | D32: Margin-based financial services
B33: [ ] | C33: Life Insurance Premiums | D33: Life insurance policies
B35: OTHER NON-RECOVERABLE
B36: [ ] | C36: Fines & Penalties | D36: Traffic fines, regulatory penalties
B37: [ ] | C37: Donations (Non-Qualifying) | D37: Donations to non-qualifying public benefit entities
B38: [ ] | C38: Expenses Without Tax Invoice | D38: Purchases without valid tax invoice
B39: [ ] | C39: Dependent Medical Insurance | D39: Voluntary coverage for employee family members
B40: [ ] | C40: Entertainment for Shareholders | D40: Hospitality for shareholders or investors
B41: [ ] | C41: Recoverable Input VAT (as cost) | D41: VAT already recovered cannot be claimed as expense
B42: [ ] | C42: Corporate Tax Payments | D42: UAE corporate tax payments are not deductible
B44: TOTAL | E44: =SUM(E5:E43) -> 0 | F44: =SUM(F5:F43) -> 0

Sheet Mixed-Use
B2: MIXED-USE EXPENSES (APPORTIONMENT REQUIRED)
B3: Enter total amount and VAT, then business-use %. Recoverable VAT auto-calculates.
B4: Check | C4: Expense Item | D4: Details | E4: Total Amount (AED) | F4: Total VAT (AED) | G4: Business Use % | H4: Recoverable VAT (AED) | I4: Non-Recoverable VAT (AED) | J4: Invoice Ref.
B5: [ ] | C5: Mobile Phone (Personal + Business) | D5: Company mobile used for both personal and business | H5: =IF(AND(F5<>"",G5<>""),F5*G5,"") | I5: =IF(AND(F5<>"",H5<>""),F5-H5,"")
B6: [ ] | C6: Vehicle (Personal + Business) | D6: Company car used for personal trips too | H6: =IF(AND(F6<>"",G6<>""),F6*G6,"") | I6: =IF(AND(F6<>"",H6<>""),F6-H6,"")
B7: [ ] | C7: Internet (Home Office) | D7: Home internet used partially for business | H7: =IF(AND(F7<>"",G7<>""),F7*G7,"") | I7: =IF(AND(F7<>"",H7<>""),F7-H7,"")
B8: [ ] | C8: Laptop / Computer (Mixed) | D8: Device used for both personal and business | H8: =IF(AND(F8<>"",G8<>""),F8*G8,"") | I8: =IF(AND(F8<>"",H8<>""),F8-H8,"")
B9: [ ] | C9: Utilities (Home Office) | D9: Home DEWA bills partially for business | H9: =IF(AND(F9<>"",G9<>""),F9*G9,"") | I9: =IF(AND(F9<>"",H9<>""),F9-H9,"")
B10: [ ] | C10: Rent (Dual-Purpose Space) | D10: Space used for both taxable and exempt activities | H10: =IF(AND(F10<>"",G10<>""),F10*G10,"") | I10: =IF(AND(F10<>"",H10<>""),F10-H10,"")
B11: [ ] | C11: Insurance (Mixed Policies) | D11: Policy covering both business and personal items | H11: =IF(AND(F11<>"",G11<>""),F11*G11,"") | I11: =IF(AND(F11<>"",H11<>""),F11-H11,"")
B12: [ ] | C12: Software (Mixed Use) | D12: Software license used partially for personal projects | H12: =IF(AND(F12<>"",G12<>""),F12*G12,"") | I12: =IF(AND(F12<>"",H12<>""),F12-H12,"")
B13: [ ] | C13: Professional Fees (Mixed) | D13: Consulting fees relating to both taxable and exempt supplies | H13: =IF(AND(F13<>"",G13<>""),F13*G13,"") | I13: =IF(AND(F13<>"",H13<>""),F13-H13,"")
B14: [ ] | C14: General Overheads (Mixed) | D14: Shared costs across taxable and exempt activities | H14: =IF(AND(F14<>"",G14<>""),F14*G14,"") | I14: =IF(AND(F14<>"",H14<>""),F14-H14,"")
B15: TOTAL | E15: =SUM(E5:E14) -> 0 | F15: =SUM(F5:F14) -> 0 | H15: =SUM(H5:H14) -> 0 | I15: =SUM(I5:I14) -> 0

Sheet Summary
B2: VAT EXPENSE SUMMARY
B3: Consolidated overview of recoverable, blocked, and mixed-use VAT
B5: Category | C5: Total Amount (AED) | D5: Total VAT (AED) | E5: Recoverable VAT (AED) | F5: Non-Recoverable VAT (AED)
B6: Recoverable Expenses | C6: =Recoverable!E98 -> 0 | D6: =Recoverable!F98 -> 0 | E6: =Recoverable!F98 -> 0 | F6: 0
B7: Blocked Expenses | C7: =Blocked!E44 -> 0 | D7: =Blocked!F44 -> 0 | E7: 0 | F7: =Blocked!F44 -> 0
B8: Mixed-Use Expenses | C8: ='Mixed-Use'!E15 -> 0 | D8: ='Mixed-Use'!F15 -> 0 | E8: ='Mixed-Use'!H15 -> 0 | F8: ='Mixed-Use'!I15 -> 0
B9: GRAND TOTAL | C9: =SUM(C6:C8) -> 0 | D9: =SUM(D6:D8) -> 0 | E9: =SUM(E6:E8) -> 0 | F9: =SUM(F6:F8) -> 0
B11: NET VAT RECOVERABLE FROM FTA | F11: =E9-F9 -> 0
B13: Note: This summary auto-populates from the Recoverable, Blocked, and Mixed-Use sheets.
B15: Sources: FTA UAE (tax.gov.ae), Maya Finance, CDA Audit, Tally Solutions, ClearTax UAE, Excellence Accounting, NOW Money
